import unittest
import os
from inspect import cleandoc
from typing import Any, List

from hstest.check_result import CheckResult
from hstest.stage_test import StageTest
from hstest.test_case import TestCase


class FeedbackOnExceptionTest1(StageTest):

    def generate(self) -> List[TestCase]:
        return [
            TestCase(feedback_on_exception={
                ZeroDivisionError: 'Do not divide by zero!'
            })
        ]

    def check(self, reply: str, attach: Any) -> CheckResult:
        return CheckResult(True, '')


class Test(unittest.TestCase):
    def test(self):
        file = __file__.replace(os.sep, '.')[:-3]
        file = file[file.find('.tests.') + 1: file.rfind('.') + 1] + 'main'
        status, feedback = FeedbackOnExceptionTest1(file).run_tests()

        self.assertEqual(cleandoc('''
            Exception in test #1
            
            Do not divide by zero!
            
            Traceback (most recent call last):
              File "main.py", line 2, in <module>
                print(1 / 0)
            ZeroDivisionError: division by zero
            
            Please find below the output of your program during this failed test.
            
            ---
            
            Hello World'''), feedback)

        self.assertEqual(status, -1)
